Workbook

Sheet README
A1: Stage 4 hand check: five auctions, every intermediate value of M1, M1b and M2
A3: Blue cells: inputs from the build (cash flows, spline z(t), model yields, DMO yields, BoE curve points).
A4: Black cells: live formulas. Green cells: links to another sheet. Yellow: the results to check.
A5: Each sheet ends with the Python result next to the spreadsheet's own, so the two can be compared.
A6: Definitions: build spec §7 and src/gilt_study/measures.py. Event days k are UK business days (= BoE curve dates).
A7: M1 = 100·(AAY - model yield off the T-1 curve, for the auction settlement date).
A8: M1b = M1 - mean residual over T-25..T-6 (days within 5 business days of an earlier auction of the gilt excluded; ≥ 10 days).
A9: M2: AR = Δy - β·Δc with β = SLOPE over k = -120..-21; CAR = 0 at T-6.
A11: Slot | B11: Auction | C11: Gilt | D11: Bucket | E11: Regime | F11: New issue | G11: Sheets
A12: short | B12: 41492 | C12: 1¼% Treasury Gilt 2018 | D12: short | E12: QE | F12: =FALSE() -> FALSE | G12: A1 M1 / M1b / M2 / control
A13: medium | B13: 40472 | C13: 3¾% Treasury Gilt 2020 | D13: medium | E13: QE | F13: =FALSE() -> FALSE | G13: A2 M1 / M1b / M2 / control
A14: long | B14: 41191 | C14: 4¼% Treasury Stock 2032 | D14: long | E14: QE | F14: =FALSE() -> FALSE | G14: A3 M1 / M1b / M2 / control
A15: new issue | B15: 43174 | C15: 1 5/8% Treasury Gilt 2028 | D15: medium | E15: QE | F15: =TRUE() -> TRUE | G15: A4 M1 / M1b / M2 / control
A16: Sept-Oct 2022 | B16: 44838 | C16: 0½% Treasury Gilt 2061 | D16: long | E16: LDI stress | F16: =FALSE() -> FALSE | G16: A5 M1 / M1b / M2 / control

Sheet A1 M1
A1: A1: 1¼% Treasury Gilt 2018, auction 06 Aug 2013 - M1 (spec §7)
A3: Auction date | B3: 41492
A4: Settlement date (DMO issue date) | B4: 41493
A5: Effective settlement (first issue date if later, decision #10) | B5: 41493
A6: Curve date (T-1 close) | B6: 41491
A7: Coupon (% p.a.) | B7: 1.25
A8: Maturity | B8: 43303
A9: First issue date | B9: 41320
A10: First coupon date (source below) | B10: 41477
A11: First coupon source | B11: DMO reference prices (accrued interest)
A12: Accrued interest at settlement (cash_flows) | B12: 0.054347826
A13: Average accepted yield, AAY (% , D2.1A) | B13: 1.405044
A14: Curve: last maturity T (y) | B14: 25
A15: Curve: z(T) (%) | B15: 3.7172686
A16: Curve: BoE forward f(T) (%) | B16: 4.1173659
A19: Cash flow date | B19: Amount per £100 | C19: t = days/365.25 | D19: z(t) % (spline; flat fwd beyond T) | E19: DF = exp(-z/100·t) | F19: PV = amount·DF | G19: Exponent (semi-annual periods) | H19: v^exponent at model yield | I19: PV at model yield | J19: BoE point below | K19: z below | L19: BoE point above | M19: z above | N19: Linear interp. of z (check)
A20: 41661 | B20: 0.625 | C20: =(A20-$B$5)/365.25 -> 0.45995893 | D20: 0.3353086 | E20: =EXP(-D20/100*C20) -> 0.99845891 | F20: =B20*E20 -> 0.62403682 | G20: 0.91304348 | H20: =(1/(1+$B$34/200))^G20 -> 0.99383942 | I20: =B20*H20 -> 0.62114963
A21: 41842 | B21: 0.625 | C21: =(A21-$B$5)/365.25 -> 0.95550992 | D21: 0.29786161 | E21: =EXP(-D21/100*C21) -> 0.99715795 | F21: =B21*E21 -> 0.62322372 | G21: 1.9130435 | H21: =(1/(1+$B$34/200))^G21 -> 0.98713565 | I21: =B21*H21 -> 0.61695978 | J21: 0.916667 | K21: 0.30075417 | L21: 1 | M21: 0.29533166 | N21: =IF(L21=J21,K21,K21+(M21-K21)*(C21-J21)/(L21-J21)) -> 0.29822665
A22: 42026 | B22: 0.625 | C22: =(A22-$B$5)/365.25 -> 1.4592745 | D22: 0.31282562 | E22: =EXP(-D22/100*C22) -> 0.99544542 | F22: =B22*E22 -> 0.62215339 | G22: 2.9130435 | H22: =(1/(1+$B$34/200))^G22 -> 0.9804771 | I22: =B22*H22 -> 0.61279818 | J22: 1.416667 | K22: 0.30819265 | L22: 1.5 | M22: 0.31775449 | N22: =IF(L22=J22,K22,K22+(M22-K22)*(C22-J22)/(L22-J22)) -> 0.31308154
A23: 42207 | B23: 0.625 | C23: =(A23-$B$5)/365.25 -> 1.9548255 | D23: 0.40096972 | E23: =EXP(-D23/100*C23) -> 0.99219238 | F23: =B23*E23 -> 0.62012024 | G23: 3.9130435 | H23: =(1/(1+$B$34/200))^G23 -> 0.97386346 | I23: =B23*H23 -> 0.60866466 | J23: 1.916667 | K23: 0.39228148 | L23: 2 | M23: 0.41159178 | N23: =IF(L23=J23,K23,K23+(M23-K23)*(C23-J23)/(L23-J23)) -> 0.40112373
A24: 42391 | B24: 0.625 | C24: =(A24-$B$5)/365.25 -> 2.45859 | D24: 0.53601413 | E24: =EXP(-D24/100*C24) -> 0.98690806 | F24: =B24*E24 -> 0.61681754 | G24: 4.9130435 | H24: =(1/(1+$B$34/200))^G24 -> 0.96729444 | I24: =B24*H24 -> 0.60455902 | J24: 2.416667 | K24: 0.52361899 | L24: 2.5 | M24: 0.54841569 | N24: =IF(L24=J24,K24,K24+(M24-K24)*(C24-J24)/(L24-J24)) -> 0.53609366
A25: 42573 | B25: 0.625 | C25: =(A25-$B$5)/365.25 -> 2.9568789 | D25: 0.69324935 | E25: =EXP(-D25/100*C25) -> 0.97971012 | F25: =B25*E25 -> 0.61231883 | G25: 5.9130435 | H25: =(1/(1+$B$34/200))^G25 -> 0.96076972 | I25: =B25*H25 -> 0.60048108 | J25: 2.916667 | K25: 0.68004151 | L25: 3 | M25: 0.70748589 | N25: =IF(L25=J25,K25,K25+(M25-K25)*(C25-J25)/(L25-J25)) -> 0.69328463
A26: 42757 | B26: 0.625 | C26: =(A26-$B$5)/365.25 -> 3.4606434 | D26: 0.86288388 | E26: =EXP(-D26/100*C26) -> 0.97058011 | F26: =B26*E26 -> 0.60661257 | G26: 6.9130435 | H26: =(1/(1+$B$34/200))^G26 -> 0.95428902 | I26: =B26*H26 -> 0.59643064 | J26: 3.416667 | K26: 0.84786756 | L26: 3.5 | M26: 0.87634176 | N26: =IF(L26=J26,K26,K26+(M26-K26)*(C26-J26)/(L26-J26)) -> 0.86289393
A27: 42938 | B27: 0.625 | C27: =(A27-$B$5)/365.25 -> 3.9561944 | D27: 1.0328832 | E27: =EXP(-D27/100*C27) -> 0.95996076 | F27: =B27*E27 -> 0.59997548 | G27: 7.9130435 | H27: =(1/(1+$B$34/200))^G27 -> 0.94785203 | I27: =B27*H27 -> 0.59240752 | J27: 3.916667 | K27: 1.01932 | L27: 4 | M27: 1.0479058 | N27: =IF(L27=J27,K27,K27+(M27-K27)*(C27-J27)/(L27-J27)) -> 1.0328791
A28: 43122 | B28: 0.625 | C28: =(A28-$B$5)/365.25 -> 4.4599589 | D28: 1.2046441 | E28: =EXP(-D28/100*C28) -> 0.94769114 | F28: =B28*E28 -> 0.59230696 | G28: 8.9130435 | H28: =(1/(1+$B$34/200))^G28 -> 0.94145846 | I28: =B28*H28 -> 0.58841154 | J28: 4.416666 | K28: 1.1899954 | L28: 4.5 | M28: 1.2181686 | N28: =IF(L28=J28,K28,K28+(M28-K28)*(C28-J28)/(L28-J28)) -> 1.2046317
A29: 43303 | B29: 100.625 | C29: =(A29-$B$5)/365.25 -> 4.9555099 | D29: 1.3701536 | E29: =EXP(-D29/100*C29) -> 0.93435568 | F29: =B29*E29 -> 94.019541 | G29: 9.9130435 | H29: =(1/(1+$B$34/200))^G29 -> 0.93510802 | I29: =B29*H29 -> 94.095244 | J29: 4.916666 | K29: 1.3573414 | L29: 5 | M29: 1.3847908 | N29: =IF(L29=J29,K29,K29+(M29-K29)*(C29-J29)/(L29-J29)) -> 1.3701362
A31: Curve dirty price = SUM(PV) | B31: =SUM(F20:F29) -> 99.537106
A32: Accrued interest | B32: =B12 -> 0.054347826
A33: Curve clean price | B33: =B31-B32 -> 99.482758
A34: Model yield (% , brentq in Python) | B34: 1.3582265
A35: Price at the model yield = SUM(PV at model yield) | B35: =SUM(I20:I29) -> 99.537106
A36: Check: price at model yield - curve dirty (≈ 0) | B36: =B35-B31 -> 1.6058266e-12
A37: M1 (bp) = 100·(AAY - model yield) | B37: =100*(B13-B34) -> 4.6817467
A38: Python M1 (bp), for comparison | B38: 4.6817467

Sheet A1 M1b
A1: A1: 1¼% Treasury Gilt 2018, auction 06 Aug 2013 - M1b baseline, T-25 to T-6 (decision #4)
A3: k (business days) | B3: Date | C3: Market yield (%): DMO yield (from the DMO clean price before 25 Nov 2002) | D3: Model yield (%, curve of that day) | E3: Residual (bp) = 100·(DMO - model) | F3: Included (1/0) | G3: Excluded because
A4: -25 | B4: 41457 | C4: 1.385677 | D4: 1.3609569 | E4: =IF(F4=1,100*(C4-D4),"") -> 2.4720106 | F4: 1
A5: -24 | B5: 41458 | C5: 1.41675 | D5: 1.3900035 | E5: =IF(F5=1,100*(C5-D5),"") -> 2.6746524 | F5: 1
A6: -23 | B6: 41459 | C6: 1.36724 | D6: 1.3502032 | E6: =IF(F6=1,100*(C6-D6),"") -> 1.7036774 | F6: 1
A7: -22 | B7: 41460 | C7: 1.435774 | D7: 1.420539 | E7: =IF(F7=1,100*(C7-D7),"") -> 1.5234986 | F7: 1
A8: -21 | B8: 41463 | C8: 1.413053 | D8: 1.4004262 | E8: =IF(F8=1,100*(C8-D8),"") -> 1.2626838 | F8: 1
A9: -20 | B9: 41464 | C9: 1.346877 | D9: 1.3350853 | E9: =IF(F9=1,100*(C9-D9),"") -> 1.1791734 | F9: 1
A10: -19 | B10: 41465 | C10: 1.351066 | D10: 1.3321427 | E10: =IF(F10=1,100*(C10-D10),"") -> 1.8923307 | F10: 1
A11: -18 | B11: 41466 | C11: 1.324276 | D11: 1.3048275 | E11: =IF(F11=1,100*(C11-D11),"") -> 1.9448515 | F11: 1
A12: -17 | B12: 41467 | C12: 1.287164 | D12: 1.2611493 | E12: =IF(F12=1,100*(C12-D12),"") -> 2.6014697 | F12: 1
A13: -16 | B13: 41470 | C13: 1.301656 | D13: 1.2788298 | E13: =IF(F13=1,100*(C13-D13),"") -> 2.2826177 | F13: 1
A14: -15 | B14: 41471 | C14: 1.229384 | D14: 1.2067978 | E14: =IF(F14=1,100*(C14-D14),"") -> 2.2586229 | F14: 1
A15: -14 | B15: 41472 | C15: 1.214938 | D15: 1.2007914 | E15: =IF(F15=1,100*(C15-D15),"") -> 1.4146608 | F15: 1
... A23: -6 | B23: 41484 | C23: 1.235442 | D23: 1.225079 | E23: =IF(F23=1,100*(C23-D23),"") -> 1.036304 | F23: 1
A25: Valid days (need ≥ 10) | B25: =SUM(F4:F23) -> 20
A26: Baseline = mean residual (bp) | B26: =IF(B25>=10,AVERAGEIF(F4:F23,1,E4:E23),"n/a") -> 1.4811281
A27: M1 (bp), from the M1 sheet | B27: ='A1 M1'!B37 -> 4.6817467
A28: M1b (bp) = M1 - baseline | B28: =IF(B25>=10,B27-B26,"n/a") -> 3.2006186
A29: Python M1b (bp), for comparison | B29: 3.2006186
A30: Python note

Sheet A1 control
A1: A1: control maturities = BoE points 2-30y more than 3y from the gilt's 4.96y to maturity (35 points). Top: z (%); bottom: daily change (bp).
A3: k | B3: Date | C3: z 8y | D3: z 8.5y | E3: z 9y | F3: z 9.5y | G3: z 10y | H3: z 10.5y | I3: z 11y | J3: z 11.5y | K3: z 12y | L3: z 12.5y | M3: z 13y | N3: z 13.5y | O3: z 14y | P3: z 14.5y | Q3: z 15y | R3: z 15.5y | S3: z 16y | T3: z 16.5y | U3: z 17y | V3: z 17.5y | W3: z 18y | X3: z 18.5y | Y3: z 19y | Z3: z 19.5y | AA3: z 20y | AB3: z 20.5y | AC3: z 21y | AD3: z 21.5y | AE3: z 22y | AF3: z 22.5y | AG3: z 23y | AH3: z 23.5y | AI3: z 24y | AJ3: z 24.5y | AK3: z 25y
A4: -121 | B4: 41317 | C4: 1.816919 | D4: 1.9262479 | E4: 2.0298525 | F4: 2.1279497 | G4: 2.220838 | H4: 2.3088253 | I4: 2.392219 | J4: 2.4713267 | K4: 2.5464555 | L4: 2.6179117 | M4: 2.6859828 | N4: 2.7509185 | O4: 2.8129343 | P4: 2.8722178 | Q4: 2.928933 | R4: 2.9832226 | S4: 3.0352063 | T4: 3.0849819 | U4: 3.1326317 | V4: 3.1782258 | W4: 3.2218241 | X4: 3.2634779 | Y4: 3.3032345 | Z4: 3.3411386 | AA4: 3.3772333 | AB4: 3.4115615 | AC4: 3.4441667 | AD4: 3.475093 | AE4: 3.5043849 | AF4: 3.5320884 | AG4: 3.5582514 | AH4: 3.5829241 | AI4: 3.6061577 | AJ4: 3.6280028 | AK4: 3.6485094
A5: -120 | B5: 41318 | C5: 1.9193873 | D5: 2.0319083 | E5: 2.138128 | F5: 2.2382804 | G5: 2.332697 | H5: 2.4217223 | I5: 2.5057026 | J5: 2.5849851 | K5: 2.6599181 | L5: 2.7308497 | M5: 2.7981073 | N5: 2.8619766 | O5: 2.9227054 | P5: 2.9805105 | Q5: 3.0355825 | R5: 3.088089 | S5: 3.1381733 | T5: 3.1859565 | U5: 3.2315425 | V5: 3.2750219 | W5: 3.3164732 | X5: 3.3559654 | Y5: 3.3935616 | Z5: 3.4293211 | AA5: 3.4632996 | AB5: 3.4955519 | AC5: 3.5261319 | AD5: 3.5550931 | AE5: 3.5824885 | AF5: 3.6083715 | AG5: 3.6327966 | AH5: 3.6558193 | AI5: 3.6774948 | AJ5: 3.697877 | AK5: 3.717018
A6: -119 | B6: 41319 | C6: 1.9103472 | D6: 2.0251798 | E6: 2.1332739 | F6: 2.2348924 | G6: 2.3303987 | H6: 2.420169 | I6: 2.5045804 | J6: 2.584011 | K6: 2.6588392 | L6: 2.7294428 | M6: 2.7961774 | N6: 2.8593536 | O6: 2.9192418 | P6: 2.9760791 | Q6: 3.0300744 | R6: 3.0814122 | S6: 3.1302507 | T6: 3.1767235 | U6: 3.2209465 | V6: 3.2630206 | W6: 3.3030345 | X6: 3.3410665 | Y6: 3.3771891 | Z6: 3.4114704 | AA6: 3.4439752 | AB6: 3.4747666 | AC6: 3.5039065 | AD6: 3.5314556 | AE6: 3.557474 | AF6: 3.5820213 | AG6: 3.6051569 | AH6: 3.6269409 | AI6: 3.6474319 | AJ6: 3.6666863 | AK6: 3.684758
A7: -118 | B7: 41320 | C7: 1.90958 | D7: 2.023471 | E7: 2.130825 | F7: 2.2319053 | G7: 2.3270602 | H7: 2.4166457 | I7: 2.5010166 | J7: 2.5805266 | K7: 2.6555283 | L7: 2.7263728 | M7: 2.7933902 | N7: 2.8568703 | O7: 2.9170672 | P7: 2.9742053 | Q7: 3.0284841 | R7: 3.0800814 | S7: 3.1291529 | T7: 3.175834 | U7: 3.2202441 | V7: 3.2624892 | W7: 3.3026637 | X7: 3.3408527 | Y7: 3.3771346 | Z7: 3.4115828 | AA7: 3.4442667 | AB7: 3.4752527 | AC7: 3.504605 | AD7: 3.5323861 | AE7: 3.5586568 | AF7: 3.5834765 | AG7: 3.6069043 | AH7: 3.6289985 | AI7: 3.649816 | AJ7: 3.6694112 | AK7: 3.6878358
A8: -117 | B8: 41323 | C8: 1.9088967 | D8: 2.0228803 | E8: 2.1303971 | F8: 2.2317051 | G8: 2.3271475 | H8: 2.4170758 | I8: 2.5018408 | J8: 2.5817926 | K8: 2.6572811 | L8: 2.7286541 | M8: 2.7962386 | N8: 2.8603202 | O8: 2.9211481 | P8: 2.9789409 | Q8: 3.0338922 | R8: 3.0861732 | S8: 3.1359318 | T8: 3.183295 | U8: 3.2283736 | V8: 3.2712661 | W8: 3.3120596 | X8: 3.3508326 | Y8: 3.3876582 | Z8: 3.4226055 | AA8: 3.4557411 | AB8: 3.4871295 | AC8: 3.5168338 | AD8: 3.5449163 | AE8: 3.5714378 | AF8: 3.5964592 | AG8: 3.6200409 | AH8: 3.6422435 | AI8: 3.6631264 | AJ8: 3.6827467 | AK8: 3.7011592
A9: -116 | B9: 41324 | C9: 1.9012873 | D9: 2.0157201 | E9: 2.1235097 | F9: 2.2249475 | G9: 2.3204138 | H9: 2.4102923 | I9: 2.4949612 | J9: 2.574795 | K9: 2.6501648 | L9: 2.7214376 | M9: 2.7889551 | N9: 2.8530129 | O9: 2.9138651 | P9: 2.9717316 | Q9: 3.0268042 | R9: 3.0792497 | S9: 3.1292102 | T9: 3.1768061 | U9: 3.2221419 | V9: 3.2653091 | W9: 3.3063884 | X9: 3.345452 | Y9: 3.3825672 | Z9: 3.4177991 | AA9: 3.4512103 | AB9: 3.4828626 | AC9: 3.5128173 | AD9: 3.5411349 | AE9: 3.5678758 | AF9: 3.5931002 | AG9: 3.6168687 | AH9: 3.6392423 | AI9: 3.6602812 | AJ9: 3.6800432 | AK9: 3.6985841
A10: -115 | B10: 41325 | C10: 1.9145634 | D10: 2.032688 | E10: 2.1434495 | F10: 2.2471697 | G10: 2.3442797 | H10: 2.4352207 | I10: 2.5204334 | J10: 2.6003581 | K10: 2.6754346 | L10: 2.7461006 | M10: 2.812766 | N10: 2.8757876 | O10: 2.935475 | P10: 2.9920987 | Q10: 3.0458965 | R10: 3.0970776 | S10: 3.1458212 | T10: 3.1922792 | U10: 3.2365819 | V10: 3.2788412 | W10: 3.3191539 | X10: 3.3576033 | Y10: 3.3942638 | Z10: 3.4292026 | AA10: 3.4624809 | AB10: 3.4941557 | AC10: 3.5242812 | AD10: 3.5529089 | AE10: 3.5800877 | AF10: 3.6058655 | AG10: 3.6302897 | AH10: 3.6534076 | AI10: 3.6752655 | AJ10: 3.6959082 | AK10: 3.7153791
A11: -114 | B11: 41326 | C11: 1.8264683 | D11: 1.9439269 | E11: 2.0543252 | F11: 2.1579186 | G11: 2.2550757 | H11: 2.3461857 | I11: 2.4316471 | J11: 2.5118648 | K11: 2.5872495 | L11: 2.6582143 | M11: 2.7251503 | N11: 2.7884023 | O11: 2.8482744 | P11: 2.9050363 | Q11: 2.9589297 | R11: 3.0101708 | S11: 3.0589483 | T11: 3.105425 | U11: 3.1497424 | V11: 3.1920233 | W11: 3.2323748 | X11: 3.2708905 | Y11: 3.3076529 | Z11: 3.3427354 | AA11: 3.3762036 | AB11: 3.4081174 | AC11: 3.4385317 | AD11: 3.4674978 | AE11: 3.4950628 | AF11: 3.5212719 | AG11: 3.5461686 | AH11: 3.5697954 | AI11: 3.5921938 | AJ11: 3.6134031 | AK11: 3.6334615
A12: -113 | B12: 41327 | C12: 1.8355159 | D12: 1.9528348 | E12: 2.0631563 | F12: 2.1667063 | G12: 2.2638279 | H12: 2.3548907 | I12: 2.4402776 | J12: 2.5203817 | K12: 2.5956046 | L12: 2.6663525 | M12: 2.7330114 | N12: 2.7959234 | O12: 2.8553919 | P12: 2.9116882 | Q12: 2.9650567 | R12: 3.0157176 | S12: 3.0638644 | T12: 3.1096659 | U12: 3.1532692 | V12: 3.1948032 | W12: 3.234381 | X12: 3.2721021 | Y12: 3.308055 | Z12: 3.3423185 | AA12: 3.3749633 | AB12: 3.4060539 | AC12: 3.4356497 | AD12: 3.4638056 | AE12: 3.4905726 | AF12: 3.5159988 | AG12: 3.5401308 | AH12: 3.5630137 | AI12: 3.5846907 | AJ12: 3.6052033 | AK12: 3.624591
A13: -112 | B13: 41330 | C13: 1.804705 | D13: 1.9224216 | E13: 2.0332265 | F13: 2.1373306 | G13: 2.2350618 | H13: 2.3267766 | I13: 2.4128471 | J13: 2.4936577 | K13: 2.5696023 | L13: 2.6410806 | M13: 2.7084735 | N13: 2.7721192 | O13: 2.8323188 | P13: 2.8893422 | Q13: 2.9434336 | R13: 2.9948133 | S13: 3.0436748 | T13: 3.0901858 | U13: 3.1344926 | V13: 3.1767229 | W13: 3.2169884 | X13: 3.2553873 | Y13: 3.2920062 | Z13: 3.3269222 | AA13: 3.3602039 | AB13: 3.3919137 | AC13: 3.4221087 | AD13: 3.4508413 | AE13: 3.4781599 | AF13: 3.50411 | AG13: 3.5287356 | AH13: 3.5520793 | AI13: 3.5741822 | AJ13: 3.595084 | AK13: 3.6148226
A14: -111 | B14: 41331 | C14: 1.6974669 | D14: 1.8114395 | E14: 1.9194361 | F14: 2.0216284 | G14: 2.1182827 | H14: 2.2096837 | I14: 2.2961249 | J14: 2.3779066 | K14: 2.4553346 | L14: 2.5287174 | M14: 2.5983472 | N14: 2.664482 | O14: 2.72735 | P14: 2.7871542 | Q14: 2.8440772 | R14: 2.8982832 | S14: 2.9499177 | T14: 2.99911 | U14: 3.0459752 | V14: 3.0906172 | W14: 3.1331297 | X14: 3.1735982 | Y14: 3.2121025 | Z14: 3.2487174 | AA14: 3.2835139 | AB14: 3.3165595 | AC14: 3.3479187 | AD14: 3.3776534 | AE14: 3.405823 | AF14: 3.4324855 | AG14: 3.4576975 | AH14: 3.4815144 | AI14: 3.5039904 | AJ14: 3.5251772 | AK14: 3.5451246
A15: -110 | B15: 41332 | C15: 1.6863868 | D15: 1.7985274 | E15: 1.904973 | F15: 2.0058671 | G15: 2.1014486 | H15: 2.1919781 | I15: 2.2777269 | J15: 2.358975 | K15: 2.4360093 | L15: 2.5091206 | M15: 2.5785847 | N15: 2.6446463 | O15: 2.7075217 | P15: 2.7674042 | Q15: 2.8244678 | R15: 2.8788696 | S15: 2.9307501 | T15: 2.9802344 | U15: 3.0274349 | V15: 3.0724524 | W15: 3.1153781 | X15: 3.156295 | Y15: 3.1952798 | Z15: 3.2324037 | AA15: 3.2677336 | AB15: 3.3013326 | AC15: 3.3332602 | AD15: 3.3635734 | AE15: 3.3923262 | AF15: 3.4195713 | AG15: 3.4453599 | AH15: 3.4697428 | AI15: 3.4927694 | AJ15: 3.5144874 | AK15: 3.5349433
... A135: 10 | B135: 41506 | C135: 2.4854435 | D135: 2.6029878 | E135: 2.7118393 | F135: 2.8123796 | G135: 2.9050113 | H135: 2.9901515 | I135: 3.0682284 | J135: 3.1396775 | K135: 3.2049393 | L135: 3.2644476 | M135: 3.3186171 | N135: 3.3678462 | O135: 3.4125192 | P135: 3.4530091 | Q135: 3.4896763 | R135: 3.5228588 | S135: 3.5528699 | T135: 3.5799986 | U135: 3.6045118 | V135: 3.6266573 | W135: 3.6466651 | X135: 3.664744 | Y135: 3.6810818 | Z135: 3.695848 | AA135: 3.7091941 | AB135: 3.7212557 | AC135: 3.7321541 | AD135: 3.7419981 | AE135: 3.7508845 | AF135: 3.7588985 | AG135: 3.7661149 | AH135: 3.7725989 | AI135: 3.7784068 | AJ135: 3.783587 | AK135: 3.7881809
A138: k | B138: Date | C138: Δz 8y (bp) | D138: Δz 8.5y (bp) | E138: Δz 9y (bp) | F138: Δz 9.5y (bp) | G138: Δz 10y (bp) | H138: Δz 10.5y (bp) | I138: Δz 11y (bp) | J138: Δz 11.5y (bp) | K138: Δz 12y (bp) | L138: Δz 12.5y (bp) | M138: Δz 13y (bp) | N138: Δz 13.5y (bp) | O138: Δz 14y (bp) | P138: Δz 14.5y (bp) | Q138: Δz 15y (bp) | R138: Δz 15.5y (bp) | S138: Δz 16y (bp) | T138: Δz 16.5y (bp) | U138: Δz 17y (bp) | V138: Δz 17.5y (bp) | W138: Δz 18y (bp) | X138: Δz 18.5y (bp) | Y138: Δz 19y (bp) | Z138: Δz 19.5y (bp) | AA138: Δz 20y (bp) | AB138: Δz 20.5y (bp) | AC138: Δz 21y (bp) | AD138: Δz 21.5y (bp) | AE138: Δz 22y (bp) | AF138: Δz 22.5y (bp) | AG138: Δz 23y (bp) | AH138: Δz 23.5y (bp) | AI138: Δz 24y (bp) | AJ138: Δz 24.5y (bp) | AK138: Δz 25y (bp) | AL138: Control Δc = average (bp)
A139: =A5 -> -120 | B139: =B5 -> 41318 | C139: =100*(C5-C4) -> 10.246838 | D139: =100*(D5-D4) -> 10.566041 | E139: =100*(E5-E4) -> 10.82755 | F139: =100*(F5-F4) -> 11.033066 | G139: =100*(G5-G4) -> 11.185893 | H139: =100*(H5-H4) -> 11.289706 | I139: =100*(I5-I4) -> 11.348357 | J139: =100*(J5-J4) -> 11.36584 | ... AK139: =100*(AK5-AK4) -> 6.8508564 | AL139: =AVERAGE(C139:AK139) -> 9.6190271
A140: =A6 -> -119 | B140: =B6 -> 41319 | C140: =100*(C6-C5) -> -0.9040123 | D140: =100*(D6-D5) -> -0.67285641 | E140: =100*(E6-E5) -> -0.48540458 | F140: =100*(F6-F5) -> -0.33879663 | G140: =100*(G6-G5) -> -0.22982808 | H140: =100*(H6-H5) -> -0.15533595 | I140: =100*(I6-I5) -> -0.11221591 | J140: =100*(J6-J5) -> -0.097409519 | ... AK140: =100*(AK6-AK5) -> -3.2260015 | AL140: =AVERAGE(C140:AK140) -> -1.2764569
A141: =A7 -> -118 | B141: =B7 -> 41320 | C141: =100*(C7-C6) -> -0.076717199 | D141: =100*(D7-D6) -> -0.17087512 | E141: =100*(E7-E6) -> -0.24489635 | F141: =100*(F7-F6) -> -0.29871365 | G141: =100*(G7-G6) -> -0.33385069 | H141: =100*(H7-H6) -> -0.35232249 | I141: =100*(I7-I6) -> -0.35637617 | J141: =100*(J7-J6) -> -0.34844052 | ... AK141: =100*(AK7-AK6) -> 0.30778378 | AL141: =AVERAGE(C141:AK141) -> -0.077583349
A142: =A8 -> -117 | B142: =B8 -> 41323 | C142: =100*(C8-C7) -> -0.0683378 | D142: =100*(D8-D7) -> -0.05907132 | E142: =100*(E8-E7) -> -0.042784399 | F142: =100*(F8-F7) -> -0.020013386 | G142: =100*(G8-G7) -> 0.0087357259 | H142: =100*(H8-H7) -> 0.043010002 | I142: =100*(I8-I7) -> 0.082416193 | J142: =100*(J8-J7) -> 0.12660777 | ... AK142: =100*(AK8-AK7) -> 1.3323435 | AL142: =AVERAGE(C142:AK142) -> 0.69613696
A143: =A9 -> -116 | B143: =B9 -> 41324 | C143: =100*(C9-C8) -> -0.76093608 | D143: =100*(D9-D8) -> -0.71602054 | E143: =100*(E9-E8) -> -0.6887475 | F143: =100*(F9-F8) -> -0.67576345 | G143: =100*(G9-G8) -> -0.67337152 | H143: =100*(H9-H8) -> -0.67835861 | I143: =100*(I9-I8) -> -0.68795978 | J143: =100*(J9-J8) -> -0.69976076 | ... AK143: =100*(AK9-AK8) -> -0.25751358 | AL143: =AVERAGE(C143:AK143) -> -0.56399721
A144: =A10 -> -115 | B144: =B10 -> 41325 | C144: =100*(C10-C9) -> 1.327609 | D144: =100*(D10-D9) -> 1.6967922 | E144: =100*(E10-E9) -> 1.993982 | F144: =100*(F10-F9) -> 2.222224 | G144: =100*(G10-G9) -> 2.3865875 | H144: =100*(H10-H9) -> 2.4928426 | I144: =100*(I10-I9) -> 2.5472188 | J144: =100*(J10-J9) -> 2.5563053 | ... AK144: =100*(AK10-AK9) -> 1.6794989 | AL144: =AVERAGE(C144:AK144) -> 1.7192386
A145: =A11 -> -114 | B145: =B11 -> 41326 | C145: =100*(C11-C10) -> -8.8095085 | D145: =100*(D11-D10) -> -8.8761105 | E145: =100*(E11-E10) -> -8.9124301 | F145: =100*(F11-F10) -> -8.9251093 | G145: =100*(G11-G10) -> -8.9204024 | H145: =100*(H11-H10) -> -8.9034944 | I145: =100*(I11-I10) -> -8.8786311 | J145: =100*(J11-J10) -> -8.849324 | ... AK145: =100*(AK11-AK10) -> -8.1917586 | AL145: =AVERAGE(C145:AK145) -> -8.6635305
A146: =A12 -> -113 | B146: =B12 -> 41327 | C146: =100*(C12-C11) -> 0.90476028 | D146: =100*(D12-D11) -> 0.89079204 | E146: =100*(E12-E11) -> 0.88311352 | F146: =100*(F12-F11) -> 0.87876196 | G146: =100*(G12-G11) -> 0.87522178 | H146: =100*(H12-H11) -> 0.8704975 | I146: =100*(I12-I11) -> 0.8630475 | J146: =100*(J12-J11) -> 0.85168544 | ... AK146: =100*(AK12-AK11) -> -0.88704695 | AL146: =AVERAGE(C146:AK146) -> 0.25465625
A147: =A13 -> -112 | B147: =B13 -> 41330 | C147: =100*(C13-C12) -> -3.0810952 | D147: =100*(D13-D12) -> -3.0413274 | E147: =100*(E13-E12) -> -2.9929839 | F147: =100*(F13-F12) -> -2.9375641 | G147: =100*(G13-G12) -> -2.8766069 | H147: =100*(H13-H12) -> -2.8114094 | I147: =100*(I13-I12) -> -2.7430425 | J147: =100*(J13-J12) -> -2.6723999 | ... AK147: =100*(AK13-AK12) -> -0.9768408 | AL147: =AVERAGE(C147:AK147) -> -1.9818232
A148: =A14 -> -111 | B148: =B14 -> 41331 | C148: =100*(C14-C13) -> -10.723806 | D148: =100*(D14-D13) -> -11.098201 | E148: =100*(E14-E13) -> -11.379043 | F148: =100*(F14-F13) -> -11.570222 | G148: =100*(G14-G13) -> -11.677913 | H148: =100*(H14-H13) -> -11.709294 | I148: =100*(I14-I13) -> -11.672226 | J148: =100*(J14-J13) -> -11.575108 | ... AK148: =100*(AK14-AK13) -> -6.9697987 | AL148: =AVERAGE(C148:AK148) -> -9.25569
A149: =A15 -> -110 | B149: =B15 -> 41332 | C149: =100*(C15-C14) -> -1.1080143 | D149: =100*(D15-D14) -> -1.2912178 | E149: =100*(E15-E14) -> -1.4463046 | F149: =100*(F15-F14) -> -1.5761334 | G149: =100*(G15-G14) -> -1.6834051 | H149: =100*(H15-H14) -> -1.7705561 | I149: =100*(I15-I14) -> -1.839796 | J149: =100*(J15-J14) -> -1.8931567 | ... AK149: =100*(AK15-AK14) -> -1.0181309 | AL149: =AVERAGE(C149:AK149) -> -1.6242995
A150: =A16 -> -109 | B150: =B16 -> 41333 | C150: =100*(C16-C15) -> 1.2438701 | D150: =100*(D16-D15) -> 1.2209135 | E150: =100*(E16-E15) -> 1.1778857 | F150: =100*(F16-F15) -> 1.1137109 | G150: =100*(G16-G15) -> 1.0284691 | H150: =100*(H16-H15) -> 0.92324823 | I150: =100*(I16-I15) -> 0.79993591 | J150: =100*(J16-J15) -> 0.66104611 | ... AK150: =100*(AK16-AK15) -> -0.85404139 | AL150: =AVERAGE(C150:AK150) -> -0.37670281
... A269: =A135 -> 10 | B269: =B135 -> 41506 | C269: =100*(C135-C134) -> -6.911752 | D269: =100*(D135-D134) -> -6.7998331 | E269: =100*(E135-E134) -> -6.6899546 | F269: =100*(F135-F134) -> -6.5813451 | G269: =100*(G135-G134) -> -6.4731703 | H269: =100*(H135-H134) -> -6.3645923 | I269: =100*(I135-I134) -> -6.2549732 | J269: =100*(J135-J134) -> -6.1440768 | ... AK269: =100*(AK135-AK134) -> -4.5592375 | AL269: =AVERAGE(C269:AK269) -> -5.3308965

Sheet A1 M2
A1: A1: 1¼% Treasury Gilt 2018, auction 06 Aug 2013 - M2 with control B-β (decision #13)
A3: k | B3: Date | C3: Model yield y (%) | D3: Δy (bp) | E3: Δc (bp), from control sheet | F3: In β window (1/0) | G3: AR B-β = Δy - β·Δc | H3: CAR B-β (base T-6) | I3: AR B (β = 1) | J3: CAR B | K3: Raw cumulative Δy
A4: -121 | B4: 41317 | C4: 1.1533278 | F4: 0
A5: -120 | B5: 41318 | C5: 1.2310134 | D5: =100*(C5-C4) -> 7.768561 | E5: ='A1 control'!AL139 -> 9.6190271 | F5: 1
A6: -119 | B6: 41319 | C6: 1.2022339 | D6: =100*(C6-C5) -> -2.8779514 | E6: ='A1 control'!AL140 -> -1.2764569 | F6: 1
A7: -118 | B7: 41320 | C7: 1.2060602 | D7: =100*(C7-C6) -> 0.38262963 | E7: ='A1 control'!AL141 -> -0.077583349 | F7: 1
A8: -117 | B8: 41323 | C8: 1.2054004 | D8: =100*(C8-C7) -> -0.065976227 | E8: ='A1 control'!AL142 -> 0.69613696 | F8: 1
A9: -116 | B9: 41324 | C9: 1.1915955 | D9: =100*(C9-C8) -> -1.3804882 | E9: ='A1 control'!AL143 -> -0.56399721 | F9: 1
A10: -115 | B10: 41325 | C10: 1.1746839 | D10: =100*(C10-C9) -> -1.6911652 | E10: ='A1 control'!AL144 -> 1.7192386 | F10: 1
A11: -114 | B11: 41326 | C11: 1.0975557 | D11: =100*(C11-C10) -> -7.7128138 | E11: ='A1 control'!AL145 -> -8.6635305 | F11: 1
A12: -113 | B12: 41327 | C12: 1.1074166 | D12: =100*(C12-C11) -> 0.98608543 | E12: ='A1 control'!AL146 -> 0.25465625 | F12: 1
A13: -112 | B13: 41330 | C13: 1.0754335 | D13: =100*(C13-C12) -> -3.1983064 | E13: ='A1 control'!AL147 -> -1.9818232 | F13: 1
A14: -111 | B14: 41331 | C14: 1.0011534 | D14: =100*(C14-C13) -> -7.4280169 | E14: ='A1 control'!AL148 -> -9.25569 | F14: 1
A15: -110 | B15: 41332 | C15: 1.0049088 | D15: =100*(C15-C14) -> 0.37554046 | E15: ='A1 control'!AL149 -> -1.6242995 | F15: 1
A16: -109 | B16: 41333 | C16: 1.0160047 | D16: =100*(C16-C15) -> 1.1095969 | E16: ='A1 control'!AL150 -> -0.37670281 | F16: 1
... A114: -11 | B114: 41477 | C114: 1.1955162 | D114: =100*(C114-C113) -> -1.1590187 | E114: ='A1 control'!AL248 -> -2.6279343 | F114: 0
A115: -10 | B115: 41478 | C115: 1.236254 | D115: =100*(C115-C114) -> 4.0737784 | E115: ='A1 control'!AL249 -> 4.4929131 | F115: 0 | G115: =D115-$B$137*E115 -> -0.031833273 | H115: =H116-G116 -> 2.4378533 | I115: =D115-E115 -> -0.41913471 | J115: =J116-I116 -> 2.5624084 | K115: =K116-D116 -> 1.1174996
A116: -9 | B116: 41479 | C116: 1.3000957 | D116: =100*(C116-C115) -> 6.3841734 | E116: ='A1 control'!AL250 -> 6.5231386 | F116: 0 | G116: =D116-$B$137*E116 -> 0.42334722 | H116: =H117-G117 -> 2.8612005 | I116: =D116-E116 -> -0.13896523 | J116: =J117-I117 -> 2.4234432 | K116: =K117-D117 -> 7.501673
A117: -8 | B117: 41480 | C117: 1.2882774 | D117: =100*(C117-C116) -> -1.1818307 | E117: ='A1 control'!AL251 -> -1.1224057 | F117: 0 | G117: =D117-$B$137*E117 -> -0.15617946 | H117: =H118-G118 -> 2.7050211 | I117: =D117-E117 -> -0.059425005 | J117: =J118-I118 -> 2.3640182 | K117: =K118-D118 -> 6.3198423
A118: -7 | B118: 41481 | C118: 1.2228583 | D118: =100*(C118-C117) -> -6.5419084 | E118: ='A1 control'!AL252 -> -3.5142685 | F118: 0 | G118: =D118-$B$137*E118 -> -3.3305795 | H118: =H119-G119 -> -0.62555838 | I118: =D118-E118 -> -3.0276399 | J118: =J119-I119 -> -0.66362168 | K118: =K119-D119 -> -0.22206611
A119: -6 | B119: 41484 | C119: 1.225079 | D119: =100*(C119-C118) -> 0.22206611 | E119: ='A1 control'!AL253 -> -0.44155556 | F119: 0 | G119: =D119-$B$137*E119 -> 0.62555838 | H119: 0 | I119: =D119-E119 -> 0.66362168 | J119: 0 | K119: 0
A120: -5 | B120: 41485 | C120: 1.2150765 | D120: =100*(C120-C119) -> -1.0002442 | E120: ='A1 control'!AL254 -> -0.83134747 | F120: 0 | G120: =D120-$B$137*E120 -> -0.24056117 | H120: =H119+G120 -> -0.24056117 | I120: =D120-E120 -> -0.16889674 | J120: =J119+I120 -> -0.16889674 | K120: =K119+D120 -> -1.0002442
A121: -4 | B121: 41486 | C121: 1.2310706 | D121: =100*(C121-C120) -> 1.5994084 | E121: ='A1 control'!AL255 -> 2.539143 | F121: 0 | G121: =D121-$B$137*E121 -> -0.72085352 | H121: =H120+G121 -> -0.9614147 | I121: =D121-E121 -> -0.93973462 | J121: =J120+I121 -> -1.1086314 | K121: =K120+D121 -> 0.59916419
A122: -3 | B122: 41487 | C122: 1.2611928 | D122: =100*(C122-C121) -> 3.0122223 | E122: ='A1 control'!AL256 -> 2.8769196 | F122: 0 | G122: =D122-$B$137*E122 -> 0.38330108 | H122: =H121+G122 -> -0.57811362 | I122: =D122-E122 -> 0.13530272 | J122: =J121+I122 -> -0.97332864 | K122: =K121+D122 -> 3.6113865
A123: -2 | B123: 41488 | C123: 1.2995957 | D123: =100*(C123-C122) -> 3.84029 | E123: ='A1 control'!AL257 -> 1.2164589 | F123: 0 | G123: =D123-$B$137*E123 -> 2.7286932 | H123: =H122+G123 -> 2.1505796 | I123: =D123-E123 -> 2.6238312 | J123: =J122+I123 -> 1.6505025 | K123: =K122+D123 -> 7.4516765
A124: -1 | B124: 41491 | C124: 1.3591222 | D124: =100*(C124-C123) -> 5.952644 | E124: ='A1 control'!AL258 -> 3.9622013 | F124: 0 | G124: =D124-$B$137*E124 -> 2.3319953 | H124: =H123+G124 -> 4.482575 | I124: =D124-E124 -> 1.9904427 | J124: =J123+I124 -> 3.6409452 | K124: =K123+D124 -> 13.404321
A125: 0 | B125: 41492 | C125: 1.3687045 | D125: =100*(C125-C124) -> 0.9582319 | E125: ='A1 control'!AL259 -> -0.15077188 | F125: 0 | G125: =D125-$B$137*E125 -> 1.0960068 | H125: =H124+G125 -> 5.5785818 | I125: =D125-E125 -> 1.1090038 | J125: =J124+I125 -> 4.749949 | K125: =K124+D125 -> 14.362552
A126: 1 | B126: 41493 | C126: 1.3844073 | D126: =100*(C126-C125) -> 1.5702862 | E126: ='A1 control'!AL260 -> 0.21967062 | F126: 0 | G126: =D126-$B$137*E126 -> 1.3695517 | H126: =H125+G126 -> 6.9481335 | I126: =D126-E126 -> 1.3506155 | J126: =J125+I126 -> 6.1005645 | K126: =K125+D126 -> 15.932839
A127: 2 | B127: 41494 | C127: 1.3735946 | D127: =100*(C127-C126) -> -1.0812754 | E127: ='A1 control'!AL261 -> 1.2469353 | F127: 0 | G127: =D127-$B$137*E127 -> -2.2207214 | H127: =H126+G127 -> 4.7274121 | I127: =D127-E127 -> -2.3282107 | J127: =J126+I127 -> 3.7723539 | K127: =K126+D127 -> 14.851563
A128: 3 | B128: 41495 | C128: 1.3489223 | D128: =100*(C128-C127) -> -2.4672269 | E128: ='A1 control'!AL262 -> -1.1079933 | F128: 0 | G128: =D128-$B$137*E128 -> -1.4547457 | H128: =H127+G128 -> 3.2726664 | I128: =D128-E128 -> -1.3592336 | J128: =J127+I128 -> 2.4131202 | K128: =K127+D128 -> 12.384336
A129: 4 | B129: 41498 | C129: 1.3644833 | D129: =100*(C129-C128) -> 1.556101 | E129: ='A1 control'!AL263 -> -0.04512396 | F129: 0 | G129: =D129-$B$137*E129 -> 1.5973352 | H129: =H128+G129 -> 4.8700016 | I129: =D129-E129 -> 1.601225 | J129: =J128+I129 -> 4.0143452 | K129: =K128+D129 -> 13.940437
A130: 5 | B130: 41499 | C130: 1.4783788 | D130: =100*(C130-C129) -> 11.389548 | E130: ='A1 control'!AL264 -> 10.524417 | F130: 0 | G130: =D130-$B$137*E130 -> 1.7723648 | H130: =H129+G130 -> 6.6423664 | I130: =D130-E130 -> 0.86513117 | J130: =J129+I130 -> 4.8794764 | K130: =K129+D130 -> 25.329985
A131: 6 | B131: 41500 | C131: 1.5228458 | D131: =100*(C131-C130) -> 4.4466976 | E131: ='A1 control'!AL265 -> 4.3853195 | F131: 0 | G131: =D131-$B$137*E131 -> 0.4394047 | H131: =H130+G131 -> 7.0817711 | I131: =D131-E131 -> 0.061378126 | J131: =J130+I131 -> 4.9408545 | K131: =K130+D131 -> 29.776683
... A135: 10 | B135: 41506 | C135: 1.5396122 | D135: =100*(C135-C134) -> -7.6493742 | E135: ='A1 control'!AL269 -> -5.3308965 | F135: 0 | G135: =D135-$B$137*E135 -> -2.7780156 | H135: =H134+G135 -> 8.3391519 | I135: =D135-E135 -> -2.3184777 | J135: =J134+I135 -> 6.1586841 | K135: =K134+D135 -> 31.453329
A137: β = SLOPE(Δy, Δc) over k = -120..-21 | B137: =SLOPE(D5:D104,E5:E104) -> 0.91379726
A138: α (estimated, not subtracted) | B138: =INTERCEPT(D5:D104,E5:E104) -> -0.035304288
A139: R² | B139: =RSQ(D5:D104,E5:E104) -> 0.783262
A140: Observations | B140: =COUNT(D5:D104) -> 100
A141: Python β, for comparison | B141: 0.91379726
A143: The PM's three numbers (bp) | B143: B-β (main) | C143: B (β = 1) | D143: Raw (no control) | E143: Python B-β
...

Sheet A2 M1
A1: A2: 3¾% Treasury Gilt 2020, auction 21 Oct 2010 - M1 (spec §7)
A3: Auction date | B3: 40472
A4: Settlement date (DMO issue date) | B4: 40473
A5: Effective settlement (first issue date if later, decision #10) | B5: 40473
A6: Curve date (T-1 close) | B6: 40471
A7: Coupon (% p.a.) | B7: 3.75
A8: Maturity | B8: 44081
A9: First issue date | B9: 40339
A10: First coupon date (source below) | B10: 40428
A11: First coupon source | B11: DMO reference prices (accrued interest)
A12: Accrued interest at settlement (cash_flows) | B12: 0.46616022
A13: Average accepted yield, AAY (% , D2.1A) | B13: 3.055442
A14: Curve: last maturity T (y) | B14: 25
A15: Curve: z(T) (%) | B15: 4.3673212
A16: Curve: BoE forward f(T) (%) | B16: 4.7136004
A19: Cash flow date | B19: Amount per £100 | C19: t = days/365.25 | D19: z(t) % (spline; flat fwd beyond T) | E19: DF = exp(-z/100·t) | F19: PV = amount·DF | G19: Exponent (semi-annual periods) | H19: v^exponent at model yield | I19: PV at model yield | J19: BoE point below | K19: z below | L19: BoE point above | M19: z above | N19: Linear interp. of z (check)
A20: 40609 | B20: 1.875 | C20: =(A20-$B$5)/365.25 -> 0.37234771 | D20: 0.54313429 | E20: =EXP(-D20/100*C20) -> 0.9979797 | F20: =B20*E20 -> 1.8712119 | G20: 0.75138122 | H20: =(1/(1+$B$44/200))^G20 -> 0.98875243 | I20: =B20*H20 -> 1.8539108 | J20: 0.333333 | K20: 0.54234811 | L20: 0.416667 | M20: 0.5449077 | N20: =IF(L20=J20,K20,K20+(M20-K20)*(C20-J20)/(L20-J20)) -> 0.54354644
A21: 40793 | B21: 1.875 | C21: =(A21-$B$5)/365.25 -> 0.87611225 | D21: 0.56743961 | E21: =EXP(-D21/100*C21) -> 0.99504093 | F21: =B21*E21 -> 1.8657017 | G21: 1.7513812 | H21: =(1/(1+$B$44/200))^G21 -> 0.97397921 | I21: =B21*H21 -> 1.826211 | J21: 0.833333 | K21: 0.56559683 | L21: 0.916667 | M21: 0.56929818 | N21: =IF(L21=J21,K21,K21+(M21-K21)*(C21-J21)/(L21-J21)) -> 0.56749691
A22: 40975 | B22: 1.875 | C22: =(A22-$B$5)/365.25 -> 1.3744011 | D22: 0.60768663 | E22: =EXP(-D22/100*C22) -> 0.99168273 | F22: =B22*E22 -> 1.8594051 | G22: 2.7513812 | H22: =(1/(1+$B$44/200))^G22 -> 0.95942672 | I22: =B22*H22 -> 1.7989251 | J22: 1.333333 | K22: 0.60259628 | L22: 1.416667 | M22: 0.6132856 | N22: =IF(L22=J22,K22,K22+(M22-K22)*(C22-J22)/(L22-J22)) -> 0.60786412
A23: 41159 | B23: 1.875 | C23: =(A23-$B$5)/365.25 -> 1.8781656 | D23: 0.69677249 | E23: =EXP(-D23/100*C23) -> 0.98699871 | F23: =B23*E23 -> 1.8506226 | G23: 3.7513812 | H23: =(1/(1+$B$44/200))^G23 -> 0.94509167 | I23: =B23*H23 -> 1.7720469 | J23: 1.833333 | K23: 0.68699884 | L23: 1.916667 | M23: 0.70542452 | N23: =IF(L23=J23,K23,K23+(M23-K23)*(C23-J23)/(L23-J23)) -> 0.69691162
A24: 41340 | B24: 1.875 | C24: =(A24-$B$5)/365.25 -> 2.3737166 | D24: 0.82432438 | E24: =EXP(-D24/100*C24) -> 0.98062307 | F24: =B24*E24 -> 1.8386683 | G24: 4.7513812 | H24: =(1/(1+$B$44/200))^G24 -> 0.9309708 | I24: =B24*H24 -> 1.7455702 | J24: 2.333333 | K24: 0.81274479 | L24: 2.416667 | M24: 0.83683838 | N24: =IF(L24=J24,K24,K24+(M24-K24)*(C24-J24)/(L24-J24)) -> 0.82442054
A25: 41524 | B25: 1.875 | C25: =(A25-$B$5)/365.25 -> 2.8774812 | D25: 0.98199778 | E25: =EXP(-D25/100*C25) -> 0.97213869 | F25: =B25*E25 -> 1.82276 | G25: 5.7513812 | H25: =(1/(1+$B$44/200))^G25 -> 0.91706091 | I25: =B25*H25 -> 1.7194892 | J25: 2.833333 | K25: 0.96735033 | L25: 2.916667 | M25: 0.99510824 | N25: =IF(L25=J25,K25,K25+(M25-K25)*(C25-J25)/(L25-J25)) -> 0.98205574
A26: 41705 | B26: 1.875 | C26: =(A26-$B$5)/365.25 -> 3.3730322 | D26: 1.1539124 | E26: =EXP(-D26/100*C26) -> 0.96182589 | F26: =B26*E26 -> 1.8034235 | G26: 6.7513812 | H26: =(1/(1+$B$44/200))^G26 -> 0.90335885 | I26: =B26*H26 -> 1.6937979 | J26: 3.333333 | K26: 1.1397335 | L26: 3.416667 | M26: 1.1695591 | N26: =IF(L26=J26,K26,K26+(M26-K26)*(C26-J26)/(L26-J26)) -> 1.153942
A27: 41889 | B27: 1.875 | C27: =(A27-$B$5)/365.25 -> 3.8767967 | D27: 1.3374617 | E27: =EXP(-D27/100*C27) -> 0.94947064 | F27: =B27*E27 -> 1.7802575 | G27: 7.7513812 | H27: =(1/(1+$B$44/200))^G27 -> 0.88986152 | I27: =B27*H27 -> 1.6684904 | J27: 3.833333 | K27: 1.3214373 | L27: 3.916667 | M27: 1.3521802 | N27: =IF(L27=J27,K27,K27+(M27-K27)*(C27-J27)/(L27-J27)) -> 1.3374716
A28: 42070 | B28: 1.875 | C28: =(A28-$B$5)/365.25 -> 4.3723477 | D28: 1.5210143 | E28: =EXP(-D28/100*C28) -> 0.93565914 | F28: =B28*E28 -> 1.7543609 | G28: 8.7513812 | H28: =(1/(1+$B$44/200))^G28 -> 0.87656586 | I28: =B28*H28 -> 1.643561 | J28: 4.333333 | K28: 1.5065522 | L28: 4.416666 | M28: 1.5374355 | N28: =IF(L28=J28,K28,K28+(M28-K28)*(C28-J28)/(L28-J28)) -> 1.5210111
A29: 42254 | B29: 1.875 | C29: =(A29-$B$5)/365.25 -> 4.8761123 | D29: 1.7067771 | E29: =EXP(-D29/100*C29) -> 0.92014467 | F29: =B29*E29 -> 1.7252713 | G29: 9.7513812 | H29: =(1/(1+$B$44/200))^G29 -> 0.86346885 | I29: =B29*H29 -> 1.6190041 | J29: 4.833333 | K29: 1.6911066 | L29: 4.916666 | M29: 1.7216088 | N29: =IF(L29=J29,K29,K29+(M29-K29)*(C29-J29)/(L29-J29)) -> 1.706765
A30: 42436 | B30: 1.875 | C30: =(A30-$B$5)/365.25 -> 5.3744011 | D30: 1.8870937 | E30: =EXP(-D30/100*C30) -> 0.90355348 | F30: =B30*E30 -> 1.6941628 | G30: 10.751381 | H30: =(1/(1+$B$44/200))^G30 -> 0.85056753 | I30: =B30*H30 -> 1.5948141 | J30: 5 | K30: 1.7520091 | L30: 5.5 | M30: 1.931778 | N30: =IF(L30=J30,K30,K30+(M30-K30)*(C30-J30)/(L30-J30)) -> 1.8866204
A31: 42620 | B31: 1.875 | C31: =(A31-$B$5)/365.25 -> 5.8781656 | D31: 2.0640563 | E31: =EXP(-D31/100*C31) -> 0.88574281 | F31: =B31*E31 -> 1.6607678 | G31: 11.751381 | H31: =(1/(1+$B$44/200))^G31 -> 0.83785897 | I31: =B31*H31 -> 1.5709856 | J31: 5.5 | K31: 1.931778 | L31: 6 | M31: 2.1058859 | N31: =IF(L31=J31,K31,K31+(M31-K31)*(C31-J31)/(L31-J31)) -> 2.0634613
... A39: 44081 | B39: 101.875 | C39: =(A39-$B$5)/365.25 -> 9.8781656 | D39: 3.1823241 | E39: =EXP(-D39/100*C39) -> 0.73025956 | F39: =B39*E39 -> 74.395193 | G39: 19.751381 | H39: =(1/(1+$B$44/200))^G39 -> 0.74279319 | I39: =B39*H39 -> 75.672057 | J39: 9.5 | K39: 3.1000603 | L39: 10 | M39: 3.2078423 | N39: =IF(L39=J39,K39,K39+(M39-K39)*(C39-J39)/(L39-J39)) -> 3.1815792
A41: Curve dirty price = SUM(PV) | B41: =SUM(F20:F39) -> 106.53781
A42: Accrued interest | B42: =B12 -> 0.46616022
A43: Curve clean price | B43: =B41-B42 -> 106.07165
A44: Model yield (% , brentq in Python) | B44: 3.0335797
A45: Price at the model yield = SUM(PV at model yield) | B45: =SUM(I20:I39) -> 106.53781
A46: Check: price at model yield - curve dirty (≈ 0) | B46: =B45-B41 -> -1.6484591e-12
A47: M1 (bp) = 100·(AAY - model yield) | B47: =100*(B13-B44) -> 2.186227
A48: Python M1 (bp), for comparison | B48: 2.186227

Sheet A2 M1b
A1: A2: 3¾% Treasury Gilt 2020, auction 21 Oct 2010 - M1b baseline, T-25 to T-6 (decision #4)
A3: k (business days) | B3: Date | C3: Market yield (%): DMO yield (from the DMO clean price before 25 Nov 2002) | D3: Model yield (%, curve of that day) | E3: Residual (bp) = 100·(DMO - model) | F3: Included (1/0) | G3: Excluded because
A4: -25 | B4: 40437 | C4: 3.247579 | D4: 3.2045084 | E4: =IF(F4=1,100*(C4-D4),"") | F4: 0 | G4: within 5 business days of an earlier auction of the gilt
A5: -24 | B5: 40438 | C5: 3.233365 | D5: 3.1894849 | E5: =IF(F5=1,100*(C5-D5),"") | F5: 0 | G5: within 5 business days of an earlier auction of the gilt
A6: -23 | B6: 40441 | C6: 3.258637 | D6: 3.2170382 | E6: =IF(F6=1,100*(C6-D6),"") | F6: 0 | G6: within 5 business days of an earlier auction of the gilt
A7: -22 | B7: 40442 | C7: 3.221585 | D7: 3.1796359 | E7: =IF(F7=1,100*(C7-D7),"") | F7: 0 | G7: within 5 business days of an earlier auction of the gilt
A8: -21 | B8: 40443 | C8: 3.073872 | D8: 3.0299246 | E8: =IF(F8=1,100*(C8-D8),"") | F8: 0 | G8: within 5 business days of an earlier auction of the gilt
A9: -20 | B9: 40444 | C9: 3.058949 | D9: 3.0082569 | E9: =IF(F9=1,100*(C9-D9),"") | F9: 0 | G9: within 5 business days of an earlier auction of the gilt
A10: -19 | B10: 40445 | C10: 3.154261 | D10: 3.0967738 | E10: =IF(F10=1,100*(C10-D10),"") -> 5.7487238 | F10: 1
A11: -18 | B11: 40448 | C11: 3.084436 | D11: 3.0286886 | E11: =IF(F11=1,100*(C11-D11),"") -> 5.5747355 | F11: 1
A12: -17 | B12: 40449 | C12: 3.041095 | D12: 2.9866461 | E12: =IF(F12=1,100*(C12-D12),"") -> 5.4448852 | F12: 1
A13: -16 | B13: 40450 | C13: 3.018266 | D13: 2.9613644 | E13: =IF(F13=1,100*(C13-D13),"") -> 5.6901625 | F13: 1
A14: -15 | B14: 40451 | C14: 3.058923 | D14: 3.0022678 | E14: =IF(F14=1,100*(C14-D14),"") -> 5.6655248 | F14: 1
A15: -14 | B15: 40452 | C15: 3.080056 | D15: 3.0235688 | E15: =IF(F15=1,100*(C15-D15),"") -> 5.6487197 | F15: 1
A16: -13 | B16: 40455 | C16: 3.035535 | D16: 2.9820274 | E16: =IF(F16=1,100*(C16-D16),"") -> 5.3507646 | F16: 1
A17: -12 | B17: 40456 | C17: 3.069478 | D17: 3.0162871 | E17: =IF(F17=1,100*(C17-D17),"") -> 5.3190933 | F17: 1
A18: -11 | B18: 40457 | C18: 3.001183 | D18: 2.9486365 | E18: =IF(F18=1,100*(C18-D18),"") -> 5.2546463 | F18: 1
A19: -10 | B19: 40458 | C19: 3.03275 | D19: 2.9792116 | E19: =IF(F19=1,100*(C19-D19),"") -> 5.3538441 | F19: 1
A20: -9 | B20: 40459 | C20: 2.966538 | D20: 2.9136022 | E20: =IF(F20=1,100*(C20-D20),"") -> 5.2935793 | F20: 1
A21: -8 | B21: 40462 | C21: 2.985569 | D21: 2.9333756 | E21: =IF(F21=1,100*(C21-D21),"") -> 5.2193434 | F21: 1
... A23: -6 | B23: 40464 | C23: 2.987469 | D23: 2.9302909 | E23: =IF(F23=1,100*(C23-D23),"") -> 5.7178111 | F23: 1
A25: Valid days (need ≥ 10) | B25: =SUM(F4:F23) -> 14
A26: Baseline = mean residual (bp) | B26: =IF(B25>=10,AVERAGEIF(F4:F23,1,E4:E23),"n/a") -> 5.4827097
A27: M1 (bp), from the M1 sheet | B27: ='A2 M1'!B47 -> 2.186227
A28: M1b (bp) = M1 - baseline | B28: =IF(B25>=10,B27-B26,"n/a") -> -3.2964827
A29: Python M1b (bp), for comparison | B29: -3.2964828
A30: Python note

Sheet A2 control
A1: A2: control maturities = BoE points 2-30y more than 3y from the gilt's 9.88y to maturity (35 points). Top: z (%); bottom: daily change (bp).
A3: k | B3: Date | C3: z 2y | D3: z 2.5y | E3: z 3y | F3: z 3.5y | G3: z 4y | H3: z 4.5y | I3: z 5y | J3: z 5.5y | K3: z 6y | L3: z 6.5y | M3: z 13y | N3: z 13.5y | O3: z 14y | P3: z 14.5y | Q3: z 15y | R3: z 15.5y | S3: z 16y | T3: z 16.5y | U3: z 17y | V3: z 17.5y | W3: z 18y | X3: z 18.5y | Y3: z 19y | Z3: z 19.5y | AA3: z 20y | AB3: z 20.5y | AC3: z 21y | AD3: z 21.5y | AE3: z 22y | AF3: z 22.5y | AG3: z 23y | AH3: z 23.5y | AI3: z 24y | AJ3: z 24.5y | AK3: z 25y
A4: -121 | B4: 40298 | C4: 1.2580122 | D4: 1.5535977 | E4: 1.8302588 | F4: 2.0872436 | G4: 2.3258397 | H4: 2.5474895 | I4: 2.7534295 | J4: 2.9446567 | K4: 3.1219581 | L4: 3.2859711 | M4: 4.4426027 | N4: 4.4765023 | O4: 4.5054576 | P4: 4.5299903 | Q4: 4.5506057 | R4: 4.5677869 | S4: 4.5819733 | T4: 4.5935608 | U4: 4.6029075 | V4: 4.6103396 | W4: 4.6161553 | X4: 4.6206203 | Y4: 4.6239557 | Z4: 4.6263424 | AA4: 4.6279288 | AB4: 4.6288354 | AC4: 4.6291584 | AD4: 4.6289719 | AE4: 4.6283301 | AF4: 4.6272695 | AG4: 4.6258127 | AH4: 4.6239747 | AI4: 4.6217641 | AJ4: 4.619184 | AK4: 4.6162349
A5: -120 | B5: 40302 | C5: 1.228425 | D5: 1.5187132 | E5: 1.7911187 | F5: 2.0442004 | G5: 2.2789836 | H5: 2.4968459 | I5: 2.6990486 | J5: 2.886647 | K5: 3.0604946 | L5: 3.2212859 | M5: 4.3598744 | N5: 4.3936228 | O5: 4.4225179 | P5: 4.4470705 | Q5: 4.4677767 | R5: 4.4851111 | S5: 4.4995058 | T5: 4.5113503 | U5: 4.5209975 | V5: 4.5287689 | W5: 4.5349588 | X5: 4.5398294 | Y5: 4.5435987 | Z5: 4.5464448 | AA5: 4.5485137 | AB5: 4.5499235 | AC5: 4.5507681 | AD5: 4.5511196 | AE5: 4.5510302 | AF5: 4.5505342 | AG5: 4.5496524 | AH5: 4.5483976 | AI5: 4.5467764 | AJ5: 4.5447902 | AK5: 4.5424373
A6: -119 | B6: 40303 | C6: 1.2064234 | D6: 1.4947954 | E6: 1.7662466 | F6: 2.0189667 | G6: 2.2537717 | H6: 2.4718952 | I6: 2.6744911 | J6: 2.8625316 | K6: 3.0368074 | L6: 3.1979694 | M6: 4.3396073 | N6: 4.3740994 | O6: 4.4038269 | P6: 4.4292899 | Q6: 4.450972 | R6: 4.4693351 | S6: 4.4847993 | T6: 4.4977435 | U6: 4.5085113 | V6: 4.5174156 | W6: 4.524743 | X6: 4.5307485 | Y6: 4.5356438 | Z6: 4.5396011 | AA6: 4.5427612 | AB6: 4.5452377 | AC6: 4.5471208 | AD6: 4.5484791 | AE6: 4.5493622 | AF6: 4.5498021 | AG6: 4.5498181 | AH6: 4.5494217 | AI6: 4.5486187 | AJ6: 4.54741 | AK6: 4.5457938
A7: -118 | B7: 40304 | C7: 1.2164453 | D7: 1.5031654 | E7: 1.7724658 | F7: 2.0228363 | G7: 2.2552227 | H7: 2.4709206 | I7: 2.6711198 | J7: 2.8568195 | K7: 3.0288337 | L7: 3.1878327 | M7: 4.3115689 | N7: 4.3453129 | O7: 4.3743544 | P7: 4.3991879 | Q7: 4.4202917 | R7: 4.438122 | S7: 4.453094 | T7: 4.4655819 | U7: 4.4759246 | V7: 4.484431 | W7: 4.491384 | X7: 4.497035 | Y7: 4.5015925 | Z7: 4.505226 | AA7: 4.5080742 | AB7: 4.5102489 | AC7: 4.5118387 | AD7: 4.5129111 | AE7: 4.5135149 | AF7: 4.5136817 | AG7: 4.5134302 | AH7: 4.5127721 | AI7: 4.5117135 | AJ7: 4.5102555 | AK7: 4.5083969
A8: -117 | B8: 40305 | C8: 1.2321721 | D8: 1.5183368 | E8: 1.7879669 | F8: 2.0394097 | G8: 2.273459 | H8: 2.4912682 | I8: 2.6938919 | J8: 2.8821952 | K8: 3.0568618 | L8: 3.2184384 | M8: 4.3471756 | N8: 4.3793409 | O8: 4.4066804 | P8: 4.4297211 | Q8: 4.4489726 | R8: 4.4649197 | S8: 4.4780016 | T8: 4.4886123 | U8: 4.4971071 | V8: 4.503808 | W8: 4.5090082 | X8: 4.5129668 | Y8: 4.5158974 | Z8: 4.5179724 | AA8: 4.5193317 | AB8: 4.5200869 | AC8: 4.5203248 | AD8: 4.5201106 | AE8: 4.5194895 | AF8: 4.5184896 | AG8: 4.517126 | AH8: 4.5154068 | AI8: 4.513335 | AJ8: 4.5109089 | AK8: 4.5081246
A9: -116 | B9: 40308 | C9: 1.2782545 | D9: 1.5737036 | E9: 1.850168 | F9: 2.1068605 | G9: 2.3450312 | H9: 2.5660912 | I9: 2.7712647 | J9: 2.9615533 | K9: 3.1377601 | L9: 3.3005323 | M9: 4.4384383 | N9: 4.4716121 | O9: 4.5000005 | P9: 4.5241185 | Q9: 4.5444626 | R9: 4.5615043 | S9: 4.5756711 | T9: 4.5873463 | U9: 4.5968762 | V9: 4.6045747 | W9: 4.6107281 | X9: 4.6155895 | Y9: 4.6193682 | Z9: 4.6222339 | AA9: 4.6243248 | AB9: 4.6257521 | AC9: 4.6266031 | AD9: 4.626944 | AE9: 4.6268221 | AF9: 4.6262678 | AG9: 4.6252991 | AH9: 4.6239272 | AI9: 4.6221584 | AJ9: 4.619994 | AK9: 4.6174336
A10: -115 | B10: 40309 | C10: 1.2712518 | D10: 1.5610236 | E10: 1.8331697 | F10: 2.0863528 | G10: 2.3214933 | H10: 2.5398447 | I10: 2.742573 | J10: 2.930674 | K10: 3.1049751 | L10: 3.2661646 | M10: 4.418996 | N10: 4.45508 | O10: 4.4863805 | P10: 4.5133673 | Q10: 4.5364944 | R10: 4.5561955 | S10: 4.5728676 | T10: 4.586872 | U10: 4.5985393 | V10: 4.6081735 | W10: 4.6160562 | X10: 4.6224401 | Y10: 4.6275389 | Z10: 4.6315308 | AA10: 4.6345657 | AB10: 4.6367687 | AC10: 4.6382436 | AD10: 4.6390745 | AE10: 4.6393274 | AF10: 4.6390519 | AG10: 4.6382852 | AH10: 4.6370567 | AI10: 4.6353897 | AJ10: 4.6333019 | AK10: 4.6308077
A11: -114 | B11: 40310 | C11: 1.1988085 | D11: 1.4856103 | E11: 1.7578653 | F11: 2.0128535 | G11: 2.2506176 | H11: 2.471871 | I11: 2.6774742 | J11: 2.8682721 | K11: 3.0450329 | L11: 3.2084367 | M11: 4.3815138 | N11: 4.4193066 | O11: 4.4523687 | P11: 4.4811631 | Q11: 4.5061358 | R11: 4.527711 | S11: 4.5462757 | T11: 4.562181 | U11: 4.5757467 | V11: 4.5872663 | W11: 4.59701 | X11: 4.6052195 | Y11: 4.6120973 | Z11: 4.6178108 | AA11: 4.6224994 | AB11: 4.6262789 | AC11: 4.6292438 | AD11: 4.6314699 | AE11: 4.633016 | AF11: 4.6339252 | AG11: 4.6342296 | AH11: 4.6339547 | AI11: 4.6331211 | AJ11: 4.6317451 | AK11: 4.6298409
A12: -113 | B12: 40311 | C12: 1.1415518 | D12: 1.42059 | E12: 1.6906177 | F12: 1.9471682 | G12: 2.1890602 | H12: 2.4161351 | I12: 2.6286026 | J12: 2.8268003 | K12: 3.0110952 | L12: 3.1818558 | M12: 4.402475 | N12: 4.4410502 | O12: 4.4746613 | P12: 4.5037969 | Q12: 4.528927 | R12: 4.5504976 | S12: 4.5689157 | T12: 4.5845503 | U12: 4.5977378 | V12: 4.6087868 | W12: 4.6179818 | X12: 4.6255772 | Y12: 4.6317878 | Z12: 4.6367921 | AA12: 4.64074 | AB12: 4.6437567 | AC12: 4.6459458 | AD12: 4.6473912 | AE12: 4.6481589 | AF12: 4.6482989 | AG12: 4.6478494 | AH12: 4.6468414 | AI12: 4.6453004 | AJ12: 4.6432472 | AK12: 4.6407
A13: -112 | B13: 40312 | C13: 1.0883679 | D13: 1.3501006 | E13: 1.608596 | F13: 1.8577853 | G13: 2.0952862 | H13: 2.3201047 | I13: 2.5318638 | J13: 2.730473 | K13: 2.9159768 | L13: 3.0884899 | M13: 4.3314362 | N13: 4.3707281 | O13: 4.4049616 | P13: 4.4346418 | Q13: 4.4602545 | R13: 4.4822606 | S13: 4.5010792 | T13: 4.5170892 | U13: 4.5306353 | V13: 4.5420326 | W13: 4.5515704 | X13: 4.5595069 | Y13: 4.5660584 | Z13: 4.5714041 | AA13: 4.5756938 | AB13: 4.5790521 | AC13: 4.5815813 | AD13: 4.5833639 | AE13: 4.5844645 | AF13: 4.584932 | AG13: 4.5848032 | AH13: 4.5841083 | AI13: 4.5828722 | AJ13: 4.5811151 | AK13: 4.578855
A14: -111 | B14: 40315 | C14: 1.0610154 | D14: 1.3201411 | E14: 1.5770977 | F14: 1.8257181 | G14: 2.0634935 | H14: 2.2892883 | I14: 2.5025793 | J14: 2.7031344 | K14: 2.890866 | L14: 3.0657681 | M14: 4.3307591 | N14: 4.3707436 | O14: 4.4055656 | P14: 4.4357425 | Q14: 4.4617724 | R14: 4.484128 | S14: 4.5032395 | T14: 4.519496 | U14: 4.5332513 | V14: 4.5448292 | W14: 4.5545272 | X14: 4.5626103 | Y14: 4.5693009 | Z14: 4.5747829 | AA14: 4.5792102 | AB14: 4.5827106 | AC14: 4.5853891 | AD14: 4.58733 | AE14: 4.5885995 | AF14: 4.5892474 | AG14: 4.5893109 | AH14: 4.5888207 | AI14: 4.5878015 | AJ14: 4.5862733 | AK14: 4.5842535
A15: -110 | B15: 40316 | C15: 1.0761647 | D15: 1.3335737 | E15: 1.5889609 | F15: 1.8363273 | G15: 2.0731466 | H15: 2.2982243 | I15: 2.5109767 | J15: 2.7111243 | K15: 2.8985475 | L15: 3.0732152 | M15: 4.3373596 | N15: 4.3774527 | O15: 4.4124185 | P15: 4.4427758 | Q15: 4.4690244 | R15: 4.4916386 | S15: 4.51105 | T15: 4.527649 | U15: 4.5417912 | V15: 4.5538017 | W15: 4.5639794 | X15: 4.5725907 | Y15: 4.5798583 | Z15: 4.5859664 | AA15: 4.5910683 | AB15: 4.5952909 | AC15: 4.5987378 | AD15: 4.6014914 | AE15: 4.6036158 | AF15: 4.6051576 | AG15: 4.6061514 | AH15: 4.6066242 | AI15: 4.6065972 | AJ15: 4.6060867 | AK15: 4.6051065
... A135: 10 | B135: 40486 | C135: 0.77594749 | D135: 0.91625428 | E135: 1.0769056 | F135: 1.2491167 | G135: 1.4263256 | H135: 1.6040872 | I135: 1.7795073 | J135: 1.9506973 | K135: 2.1163757 | L135: 2.2756403 | M135: 3.6786301 | N135: 3.7421359 | O135: 3.8009512 | P135: 3.8553762 | Q135: 3.9056968 | R135: 3.9521776 | S135: 3.9950584 | T135: 4.0345566 | U135: 4.0708709 | V135: 4.1041845 | W135: 4.1346692 | X135: 4.162491 | Y135: 4.1878102 | Z135: 4.2107821 | AA135: 4.231557 | AB135: 4.2502811 | AC135: 4.2670968 | AD135: 4.2821432 | AE135: 4.2955563 | AF135: 4.3074664 | AG135: 4.3179958 | AH135: 4.327259 | AI135: 4.3353638 | AJ135: 4.3424115 | AK135: 4.3484957
A138: k | B138: Date | C138: Δz 2y (bp) | D138: Δz 2.5y (bp) | E138: Δz 3y (bp) | F138: Δz 3.5y (bp) | G138: Δz 4y (bp) | H138: Δz 4.5y (bp) | I138: Δz 5y (bp) | J138: Δz 5.5y (bp) | K138: Δz 6y (bp) | L138: Δz 6.5y (bp) | M138: Δz 13y (bp) | N138: Δz 13.5y (bp) | O138: Δz 14y (bp) | P138: Δz 14.5y (bp) | Q138: Δz 15y (bp) | R138: Δz 15.5y (bp) | S138: Δz 16y (bp) | T138: Δz 16.5y (bp) | U138: Δz 17y (bp) | V138: Δz 17.5y (bp) | W138: Δz 18y (bp) | X138: Δz 18.5y (bp) | Y138: Δz 19y (bp) | Z138: Δz 19.5y (bp) | AA138: Δz 20y (bp) | AB138: Δz 20.5y (bp) | AC138: Δz 21y (bp) | AD138: Δz 21.5y (bp) | AE138: Δz 22y (bp) | AF138: Δz 22.5y (bp) | AG138: Δz 23y (bp) | AH138: Δz 23.5y (bp) | AI138: Δz 24y (bp) | AJ138: Δz 24.5y (bp) | AK138: Δz 25y (bp) | AL138: Control Δc = average (bp)
A139: =A5 -> -120 | B139: =B5 -> 40302 | C139: =100*(C5-C4) -> -2.9587183 | D139: =100*(D5-D4) -> -3.4884487 | E139: =100*(E5-E4) -> -3.91401 | F139: =100*(F5-F4) -> -4.304319 | G139: =100*(G5-G4) -> -4.6856035 | H139: =100*(H5-H4) -> -5.0643573 | I139: =100*(I5-I4) -> -5.4380959 | J139: =100*(J5-J4) -> -5.8009647 | ... AK139: =100*(AK5-AK4) -> -7.3797566 | AL139: =AVERAGE(C139:AK139) -> -7.0673938
A140: =A6 -> -119 | B140: =B6 -> 40303 | C140: =100*(C6-C5) -> -2.2001598 | D140: =100*(D6-D5) -> -2.3917819 | E140: =100*(E6-E5) -> -2.487211 | F140: =100*(F6-F5) -> -2.523364 | G140: =100*(G6-G5) -> -2.5211927 | H140: =100*(H6-H5) -> -2.4950728 | I140: =100*(I6-I5) -> -2.4557514 | J140: =100*(J6-J5) -> -2.4115413 | ... AK140: =100*(AK6-AK5) -> 0.3356525 | AL140: =AVERAGE(C140:AK140) -> -1.2773524
A141: =A7 -> -118 | B141: =B7 -> 40304 | C141: =100*(C7-C6) -> 1.0021873 | D141: =100*(D7-D6) -> 0.83700016 | E141: =100*(E7-E6) -> 0.62192041 | F141: =100*(F7-F6) -> 0.38695703 | G141: =100*(G7-G6) -> 0.14510084 | H141: =100*(H7-H6) -> -0.097458895 | I141: =100*(I7-I6) -> -0.33712128 | J141: =100*(J7-J6) -> -0.57121219 | ... AK141: =100*(AK7-AK6) -> -3.7396971 | AL141: =AVERAGE(C141:AK141) -> -2.3955839
A142: =A8 -> -117 | B142: =B8 -> 40305 | C142: =100*(C8-C7) -> 1.5726773 | D142: =100*(D8-D7) -> 1.5171457 | E142: =100*(E8-E7) -> 1.5501174 | F142: =100*(F8-F7) -> 1.6573405 | G142: =100*(G8-G7) -> 1.8236266 | H142: =100*(H8-H7) -> 2.0347608 | I142: =100*(I8-I7) -> 2.277204 | J142: =100*(J8-J7) -> 2.5375691 | ... AK142: =100*(AK8-AK7) -> -0.027231957 | AL142: =AVERAGE(C142:AK142) -> 1.7180353
A143: =A9 -> -116 | B143: =B9 -> 40308 | C143: =100*(C9-C8) -> 4.6082422 | D143: =100*(D9-D8) -> 5.5366749 | E143: =100*(E9-E8) -> 6.220111 | F143: =100*(F9-F8) -> 6.7450787 | G143: =100*(G9-G8) -> 7.1572242 | H143: =100*(H9-H8) -> 7.4823041 | I143: =100*(I9-I8) -> 7.737283 | J143: =100*(J9-J8) -> 7.9358104 | ... AK143: =100*(AK9-AK8) -> 10.930909 | AL143: =AVERAGE(C143:AK143) -> 9.2924319
A144: =A10 -> -115 | B144: =B10 -> 40309 | C144: =100*(C10-C9) -> -0.70026638 | D144: =100*(D10-D9) -> -1.2679952 | E144: =100*(E10-E9) -> -1.6998355 | F144: =100*(F10-F9) -> -2.0507657 | G144: =100*(G10-G9) -> -2.3537945 | H144: =100*(H10-H9) -> -2.624653 | I144: =100*(I10-I9) -> -2.8691701 | J144: =100*(J10-J9) -> -3.0879297 | ... AK144: =100*(AK10-AK9) -> 1.3374026 | AL144: =AVERAGE(C144:AK144) -> -0.39812019
A145: =A11 -> -114 | B145: =B11 -> 40310 | C145: =100*(C11-C10) -> -7.2443347 | D145: =100*(D11-D10) -> -7.5413309 | E145: =100*(E11-E10) -> -7.5304381 | F145: =100*(F11-F10) -> -7.3499339 | G145: =100*(G11-G10) -> -7.0875713 | H145: =100*(H11-H10) -> -6.7973732 | I145: =100*(I11-I10) -> -6.5098776 | J145: =100*(J11-J10) -> -6.2401883 | ... AK145: =100*(AK11-AK10) -> -0.096678495 | AL145: =AVERAGE(C145:AK145) -> -3.1484415
A146: =A12 -> -113 | B146: =B12 -> 40311 | C146: =100*(C12-C11) -> -5.7256694 | D146: =100*(D12-D11) -> -6.5020373 | E146: =100*(E12-E11) -> -6.7247571 | F146: =100*(F12-F11) -> -6.5685315 | G146: =100*(G12-G11) -> -6.1557401 | H146: =100*(H12-H11) -> -5.573588 | I146: =100*(I12-I11) -> -4.8871592 | J146: =100*(J12-J11) -> -4.1471804 | ... AK146: =100*(AK12-AK11) -> 1.0859091 | AL146: =AVERAGE(C146:AK146) -> -0.1792259
A147: =A13 -> -112 | B147: =B13 -> 40312 | C147: =100*(C13-C12) -> -5.3183826 | D147: =100*(D13-D12) -> -7.0489356 | E147: =100*(E13-E12) -> -8.2021751 | F147: =100*(F13-F12) -> -8.9382901 | G147: =100*(G13-G12) -> -9.3773955 | H147: =100*(H13-H12) -> -9.6030424 | I147: =100*(I13-I12) -> -9.6738861 | J147: =100*(J13-J12) -> -9.6327278 | ... AK147: =100*(AK13-AK12) -> -6.1844951 | AL147: =AVERAGE(C147:AK147) -> -7.1819991
A148: =A14 -> -111 | B148: =B14 -> 40315 | C148: =100*(C14-C13) -> -2.7352547 | D148: =100*(D14-D13) -> -2.9959517 | E148: =100*(E14-E13) -> -3.1498336 | F148: =100*(F14-F13) -> -3.2067239 | G148: =100*(G14-G13) -> -3.1792665 | H148: =100*(H14-H13) -> -3.0816361 | I148: =100*(I14-I13) -> -2.928447 | J148: =100*(J14-J13) -> -2.7338622 | ... AK148: =100*(AK14-AK13) -> 0.5398435 | AL148: =AVERAGE(C148:AK148) -> -0.60784933
A149: =A15 -> -110 | B149: =B15 -> 40316 | C149: =100*(C15-C14) -> 1.5149313 | D149: =100*(D15-D14) -> 1.3432641 | E149: =100*(E15-E14) -> 1.1863238 | F149: =100*(F15-F14) -> 1.0609254 | G149: =100*(G15-G14) -> 0.96530384 | H149: =100*(H15-H14) -> 0.89360046 | I149: =100*(I15-I14) -> 0.8397361 | J149: =100*(J15-J14) -> 0.7989928 | ... AK149: =100*(AK15-AK14) -> 2.0853022 | AL149: =AVERAGE(C149:AK149) -> 1.1278521
A150: =A16 -> -109 | B150: =B16 -> 40317 | C150: =100*(C16-C15) -> -4.0541424 | D150: =100*(D16-D15) -> -5.3631465 | E150: =100*(E16-E15) -> -6.4100501 | F150: =100*(F16-F15) -> -7.2279131 | G150: =100*(G16-G15) -> -7.8558649 | H150: =100*(H16-H15) -> -8.3289577 | I150: =100*(I16-I15) -> -8.6766984 | J150: =100*(J16-J15) -> -8.9234887 | ... AK150: =100*(AK16-AK15) -> -8.1585103 | AL150: =AVERAGE(C150:AK150) -> -8.1479114
... A269: =A135 -> 10 | B269: =B135 -> 40486 | C269: =100*(C135-C134) -> -2.9546059 | D269: =100*(D135-D134) -> -3.4295928 | E269: =100*(E135-E134) -> -3.8155851 | F269: =100*(F135-F134) -> -4.1351743 | G269: =100*(G135-G134) -> -4.3960319 | H269: =100*(H135-H134) -> -4.6027829 | I269: =100*(I135-I134) -> -4.7595701 | J269: =100*(J135-J134) -> -4.8703945 | ... AK269: =100*(AK135-AK134) -> 0.66458859 | AL269: =AVERAGE(C269:AK269) -> -1.8698411

Sheet A2 M2
A1: A2: 3¾% Treasury Gilt 2020, auction 21 Oct 2010 - M2 with control B-β (decision #13)
A3: k | B3: Date | C3: Model yield y (%) | D3: Δy (bp) | E3: Δc (bp), from control sheet | F3: In β window (1/0) | G3: AR B-β = Δy - β·Δc | H3: CAR B-β (base T-6) | I3: AR B (β = 1) | J3: CAR B | K3: Raw cumulative Δy
A4: -121 | B4: 40298 | C4: 4.0003259 | F4: 0
A5: -120 | B5: 40302 | C5: 3.9231928 | D5: =100*(C5-C4) -> -7.7133152 | E5: ='A2 control'!AL139 -> -7.0673938 | F5: 1
A6: -119 | B6: 40303 | C6: 3.9003658 | D6: =100*(C6-C5) -> -2.2826966 | E6: ='A2 control'!AL140 -> -1.2773524 | F6: 1
A7: -118 | B7: 40304 | C7: 3.8800251 | D7: =100*(C7-C6) -> -2.0340724 | E7: ='A2 control'!AL141 -> -2.3955839 | F7: 1
A8: -117 | B8: 40305 | C8: 3.9189638 | D8: =100*(C8-C7) -> 3.8938698 | E8: ='A2 control'!AL142 -> 1.7180353 | F8: 1
A9: -116 | B9: 40308 | C9: 4.0049311 | D9: =100*(C9-C8) -> 8.5967328 | E9: ='A2 control'!AL143 -> 9.2924319 | F9: 1
A10: -115 | B10: 40309 | C10: 3.9721514 | D10: =100*(C10-C9) -> -3.2779763 | E10: ='A2 control'!AL144 -> -0.39812019 | F10: 1
A11: -114 | B11: 40310 | C11: 3.9235318 | D11: =100*(C11-C10) -> -4.8619614 | E11: ='A2 control'!AL145 -> -3.1484415 | F11: 1
A12: -113 | B12: 40311 | C12: 3.9279661 | D12: =100*(C12-C11) -> 0.44343846 | E12: ='A2 control'!AL146 -> -0.1792259 | F12: 1
A13: -112 | B13: 40312 | C13: 3.8484263 | D13: =100*(C13-C12) -> -7.9539844 | E13: ='A2 control'!AL147 -> -7.1819991 | F13: 1
A14: -111 | B14: 40315 | C14: 3.8389614 | D14: =100*(C14-C13) -> -0.9464896 | E14: ='A2 control'!AL148 -> -0.60784933 | F14: 1
A15: -110 | B15: 40316 | C15: 3.845909 | D15: =100*(C15-C14) -> 0.6947596 | E15: ='A2 control'!AL149 -> 1.1278521 | F15: 1
A16: -109 | B16: 40317 | C16: 3.7559735 | D16: =100*(C16-C15) -> -8.993554 | E16: ='A2 control'!AL150 -> -8.1479114 | F16: 1
... A114: -11 | B114: 40457 | C114: 2.9486365 | D114: =100*(C114-C113) -> -6.765053 | E114: ='A2 control'!AL248 -> -3.6677258 | F114: 0
A115: -10 | B115: 40458 | C115: 2.9792116 | D115: =100*(C115-C114) -> 3.0575022 | E115: ='A2 control'!AL249 -> 2.8850581 | F115: 0 | G115: =D115-$B$137*E115 -> 0.051516416 | H115: =H116-G116 -> 4.5546704 | I115: =D115-E115 -> 0.17244409 | J115: =J116-I116 -> 4.5682435 | K115: =K116-D116 -> 4.892067
A116: -9 | B116: 40459 | C116: 2.9136022 | D116: =100*(C116-C115) -> -6.5609352 | E116: ='A2 control'!AL250 -> -5.0721371 | F116: 0 | G116: =D116-$B$137*E116 -> -1.2761987 | H116: =H117-G117 -> 3.2784717 | I116: =D116-E116 -> -1.4887981 | J116: =J117-I117 -> 3.0794454 | K116: =K117-D117 -> -1.6688682
A117: -8 | B117: 40462 | C117: 2.9333756 | D117: =100*(C117-C116) -> 1.9773359 | E117: ='A2 control'!AL251 -> 3.5424386 | F117: 0 | G117: =D117-$B$137*E117 -> -1.7135846 | H117: =H118-G118 -> 1.5648871 | I117: =D117-E117 -> -1.5651027 | J117: =J118-I118 -> 1.5143427 | K117: =K118-D118 -> 0.30846769
A118: -7 | B118: 40463 | C118: 2.897857 | D118: =100*(C118-C117) -> -3.5518588 | E118: ='A2 control'!AL252 -> -1.7164386 | F118: 0 | G118: =D118-$B$137*E118 -> -1.7634754 | H118: =H119-G119 -> -0.19858828 | I118: =D118-E118 -> -1.8354202 | J118: =J119-I119 -> -0.32107753 | K118: =K119-D119 -> -3.2433911
A119: -6 | B119: 40464 | C119: 2.9302909 | D119: =100*(C119-C118) -> 3.2433911 | E119: ='A2 control'!AL253 -> 2.9223136 | F119: 0 | G119: =D119-$B$137*E119 -> 0.19858828 | H119: 0 | I119: =D119-E119 -> 0.32107753 | J119: 0 | K119: 0
A120: -5 | B120: 40465 | C120: 2.9299827 | D120: =100*(C120-C119) -> -0.030813971 | E120: ='A2 control'!AL254 -> 0.13135032 | F120: 0 | G120: =D120-$B$137*E120 -> -0.16766986 | H120: =H119+G120 -> -0.16766986 | I120: =D120-E120 -> -0.16216429 | J120: =J119+I120 -> -0.16216429 | K120: =K119+D120 -> -0.030813971
A121: -4 | B121: 40466 | C121: 2.9925805 | D121: =100*(C121-C120) -> 6.2597737 | E121: ='A2 control'!AL255 -> 7.1224918 | F121: 0 | G121: =D121-$B$137*E121 -> -1.1612584 | H121: =H120+G121 -> -1.3289283 | I121: =D121-E121 -> -0.86271805 | J121: =J120+I121 -> -1.0248823 | K121: =K120+D121 -> 6.2289597
